{
  try {
    doTest(script);
    fail("did not get expected exception");
  }
 catch (  ScriptException expected) {
    Throwable cause=expected.getCause();
    assertNotNull(cause);
    if (exceptionClass.isAssignableFrom(cause.getClass()) == false) {
      throw new AssertionError("unexpected exception: " + cause,expected);
    }
  }
}
